<?xml version="1.0" ?>
<robot name="urdf_0816" xmlns:xacro="http://www.ros.org/wiki/xacro">

<xacro:include filename="$(find urdf_0816_description)/urdf/materials.xacro" />
<xacro:include filename="$(find urdf_0816_description)/urdf/urdf_0816.trans" />
<link name="base_link">
  <inertial>
    <origin xyz="-0.040820856158367766 0.00036104809684655377 0.015213618835662102" rpy="0 0 0"/>
    <mass value="0.700086994811545"/>
    <inertia ixx="0.001733" iyy="0.002626" izz="0.004024" ixy="1.7e-05" iyz="-4e-06" ixz="-2.5e-05"/>
  </inertial>
  <visual>
    <origin xyz="0 0 0" rpy="0 0 0"/>
    <geometry>
      <mesh filename="package://urdf_0816_description/meshes/base_link.stl" scale="0.001 0.001 0.001"/>
    </geometry>
    <material name="steel_satin"/>
  </visual>
  <collision>
    <origin xyz="0 0 0" rpy="0 0 0"/>
    <geometry>
      <mesh filename="package://urdf_0816_description/meshes/base_link.stl" scale="0.001 0.001 0.001"/>
    </geometry>
  </collision>
</link>

<link name="link1_1">
  <inertial>
    <origin xyz="-0.00010633595242580096 0.00020725329457724776 0.026966319767860035" rpy="0 0 0"/>
    <mass value="0.28442007333799074"/>
    <inertia ixx="0.000333" iyy="0.000325" izz="0.000378" ixy="0.0" iyz="-2e-06" ixz="-1e-06"/>
  </inertial>
  <visual>
    <origin xyz="0.0 -0.0 -0.0555" rpy="0 0 0"/>
    <geometry>
      <mesh filename="package://urdf_0816_description/meshes/link1_1.stl" scale="0.001 0.001 0.001"/>
    </geometry>
    <material name="silver_default"/>
  </visual>
  <collision>
    <origin xyz="0.0 -0.0 -0.0555" rpy="0 0 0"/>
    <geometry>
      <mesh filename="package://urdf_0816_description/meshes/link1_1.stl" scale="0.001 0.001 0.001"/>
    </geometry>
  </collision>
</link>

<link name="link6_1">
  <inertial>
    <origin xyz="1.0851645860010528e-05 -0.011072592980630363 -0.021361276335835733" rpy="0 0 0"/>
    <mass value="0.4351295137369132"/>
    <inertia ixx="0.000158" iyy="0.000105" izz="0.000113" ixy="-0.0" iyz="-6e-06" ixz="-0.0"/>
  </inertial>
  <visual>
    <origin xyz="-0.534035 -0.000358 -0.4904" rpy="0 0 0"/>
    <geometry>
      <mesh filename="package://urdf_0816_description/meshes/link6_1.stl" scale="0.001 0.001 0.001"/>
    </geometry>
    <material name="silver_default"/>
  </visual>
  <collision>
    <origin xyz="-0.534035 -0.000358 -0.4904" rpy="0 0 0"/>
    <geometry>
      <mesh filename="package://urdf_0816_description/meshes/link6_1.stl" scale="0.001 0.001 0.001"/>
    </geometry>
  </collision>
</link>

<link name="link5_1">
  <inertial>
    <origin xyz="0.011649390529319126 -0.018561235276543478 -0.04427731409723035" rpy="0 0 0"/>
    <mass value="0.149123060567995"/>
    <inertia ixx="4.1e-05" iyy="4.6e-05" izz="4.4e-05" ixy="0.0" iyz="-1e-06" ixz="3e-06"/>
  </inertial>
  <visual>
    <origin xyz="-0.534018 -0.019258 -0.5552" rpy="0 0 0"/>
    <geometry>
      <mesh filename="package://urdf_0816_description/meshes/link5_1.stl" scale="0.001 0.001 0.001"/>
    </geometry>
    <material name="silver_default"/>
  </visual>
  <collision>
    <origin xyz="-0.534018 -0.019258 -0.5552" rpy="0 0 0"/>
    <geometry>
      <mesh filename="package://urdf_0816_description/meshes/link5_1.stl" scale="0.001 0.001 0.001"/>
    </geometry>
  </collision>
</link>

<link name="EndEffector_1">
  <inertial>
    <origin xyz="4.291544277090775e-05 -0.0036152140147807737 0.004889155227827402" rpy="0 0 0"/>
    <mass value="0.2999455316821713"/>
    <inertia ixx="0.000109" iyy="0.000236" izz="0.000277" ixy="-0.0" iyz="2e-06" ixz="-0.0"/>
  </inertial>
  <visual>
    <origin xyz="-0.533985 -0.000358 -0.4454" rpy="0 0 0"/>
    <geometry>
      <mesh filename="package://urdf_0816_description/meshes/EndEffector_1.stl" scale="0.001 0.001 0.001"/>
    </geometry>
    <material name="opaque02550"/>
  </visual>
  <collision>
    <origin xyz="-0.533985 -0.000358 -0.4454" rpy="0 0 0"/>
    <geometry>
      <mesh filename="package://urdf_0816_description/meshes/EndEffector_1.stl" scale="0.001 0.001 0.001"/>
    </geometry>
  </collision>
</link>

<link name="right_finger_1">
  <inertial>
    <origin xyz="-0.010602105454361022 -4.707945734816726e-05 -0.034038644156227704" rpy="0 0 0"/>
    <mass value="0.3076182712077128"/>
    <inertia ixx="0.000538" iyy="0.000254" izz="0.000321" ixy="0.0" iyz="-0.0" ixz="-3.9e-05"/>
  </inertial>
  <visual>
    <origin xyz="-0.588985 -0.000431 -0.4374" rpy="0 0 0"/>
    <geometry>
      <mesh filename="package://urdf_0816_description/meshes/right_finger_1.stl" scale="0.001 0.001 0.001"/>
    </geometry>
    <material name="steel_satin"/>
  </visual>
  <collision>
    <origin xyz="-0.588985 -0.000431 -0.4374" rpy="0 0 0"/>
    <geometry>
      <mesh filename="package://urdf_0816_description/meshes/right_finger_1.stl" scale="0.001 0.001 0.001"/>
    </geometry>
  </collision>
</link>

<link name="left_finger_1">
  <inertial>
    <origin xyz="0.010602170828002466 -2.819158263641687e-05 -0.03403902699335176" rpy="0 0 0"/>
    <mass value="0.30761816326804103"/>
    <inertia ixx="0.000538" iyy="0.000254" izz="0.000321" ixy="0.0" iyz="-0.0" ixz="3.9e-05"/>
  </inertial>
  <visual>
    <origin xyz="-0.478985 -0.000286 -0.4374" rpy="0 0 0"/>
    <geometry>
      <mesh filename="package://urdf_0816_description/meshes/left_finger_1.stl" scale="0.001 0.001 0.001"/>
    </geometry>
    <material name="steel_satin"/>
  </visual>
  <collision>
    <origin xyz="-0.478985 -0.000286 -0.4374" rpy="0 0 0"/>
    <geometry>
      <mesh filename="package://urdf_0816_description/meshes/left_finger_1.stl" scale="0.001 0.001 0.001"/>
    </geometry>
  </collision>
</link>

<link name="link2_1">
  <inertial>
    <origin xyz="0.0060522563742429385 -0.03069852838470896 0.26309687039061297" rpy="0 0 0"/>
    <mass value="2.088012841774827"/>
    <inertia ixx="0.049506" iyy="0.049552" izz="0.000925" ixy="6.4e-05" iyz="0.00105" ixz="-0.00211"/>
  </inertial>
  <visual>
    <origin xyz="3.7e-05 -0.024464 -0.12355" rpy="0 0 0"/>
    <geometry>
      <mesh filename="package://urdf_0816_description/meshes/link2_1.stl" scale="0.001 0.001 0.001"/>
    </geometry>
    <material name="silver_default"/>
  </visual>
  <collision>
    <origin xyz="3.7e-05 -0.024464 -0.12355" rpy="0 0 0"/>
    <geometry>
      <mesh filename="package://urdf_0816_description/meshes/link2_1.stl" scale="0.001 0.001 0.001"/>
    </geometry>
  </collision>
</link>

<link name="link4_1">
  <inertial>
    <origin xyz="0.04200033140116871 0.00507003235961316 -1.2073697562842156e-06" rpy="0 0 0"/>
    <mass value="0.828744250174943"/>
    <inertia ixx="0.00023" iyy="0.000619" izz="0.000688" ixy="9.5e-05" iyz="0.0" ixz="-0.0"/>
  </inertial>
  <visual>
    <origin xyz="-0.455435 -0.000288 -0.5552" rpy="0 0 0"/>
    <geometry>
      <mesh filename="package://urdf_0816_description/meshes/link4_1.stl" scale="0.001 0.001 0.001"/>
    </geometry>
    <material name="silver_default"/>
  </visual>
  <collision>
    <origin xyz="-0.455435 -0.000288 -0.5552" rpy="0 0 0"/>
    <geometry>
      <mesh filename="package://urdf_0816_description/meshes/link4_1.stl" scale="0.001 0.001 0.001"/>
    </geometry>
  </collision>
</link>

<link name="link3_1">
  <inertial>
    <origin xyz="0.19536238170651474 -0.019556966486173572 0.00017773410978028092" rpy="0 0 0"/>
    <mass value="1.722735495745173"/>
    <inertia ixx="0.000514" iyy="0.031424" izz="0.03162" ixy="-0.001219" iyz="1e-06" ixz="5.5e-05"/>
  </inertial>
  <visual>
    <origin xyz="-0.034824 -0.012495 -0.5553" rpy="0 0 0"/>
    <geometry>
      <mesh filename="package://urdf_0816_description/meshes/link3_1.stl" scale="0.001 0.001 0.001"/>
    </geometry>
    <material name="silver_default"/>
  </visual>
  <collision>
    <origin xyz="-0.034824 -0.012495 -0.5553" rpy="0 0 0"/>
    <geometry>
      <mesh filename="package://urdf_0816_description/meshes/link3_1.stl" scale="0.001 0.001 0.001"/>
    </geometry>
  </collision>
</link>

<joint name="Revolute_1" type="continuous">
  <origin xyz="0.0 0.0 0.0555" rpy="0 0 0"/>
  <parent link="base_link"/>
  <child link="link1_1"/>
  <axis xyz="-0.0 0.0 1.0"/>
</joint>

<joint name="Revolute_6" type="continuous">
  <origin xyz="1.7e-05 -0.0189 -0.0648" rpy="0 0 0"/>
  <parent link="link5_1"/>
  <child link="link6_1"/>
  <axis xyz="0.0 0.0 -1.0"/>
</joint>

<joint name="Revolute_5" type="continuous">
  <origin xyz="0.078583 0.01897 0.0" rpy="0 0 0"/>
  <parent link="link4_1"/>
  <child link="link5_1"/>
  <axis xyz="-0.000898 1.0 0.0"/>
</joint>

<joint name="Rigid_7" type="fixed">
  <origin xyz="-5e-05 0.0 -0.045" rpy="0 0 0"/>
  <parent link="link6_1"/>
  <child link="EndEffector_1"/>
</joint>

<joint name="Slider_1" type="prismatic">
  <origin xyz="0.055 7.3e-05 -0.008" rpy="0 0 0"/>
  <parent link="EndEffector_1"/>
  <child link="right_finger_1"/>
  <axis xyz="-1.0 -0.000898 -0.0"/>
  <limit upper="0.024" lower="0.0" effort="100" velocity="100"/>
</joint>

<joint name="Slider_2" type="prismatic">
  <origin xyz="-0.055 -7.2e-05 -0.008" rpy="0 0 0"/>
  <parent link="EndEffector_1"/>
  <child link="left_finger_1"/>
  <axis xyz="-1.0 -0.000898 -0.0"/>
  <limit upper="0.0" lower="-0.024" effort="100" velocity="100"/>
</joint>

<joint name="Revolute_2" type="revolute">
  <origin xyz="-3.7e-05 0.024464 0.06805" rpy="0 0 0"/>
  <parent link="link1_1"/>
  <child link="link2_1"/>
  <axis xyz="-0.000898 1.0 -0.0"/>
  <limit upper="1.570796" lower="-1.570796" effort="100" velocity="100"/>
</joint>

<joint name="Revolute_4" type="continuous">
  <origin xyz="0.420611 -0.012207 -0.0001" rpy="0 0 0"/>
  <parent link="link3_1"/>
  <child link="link4_1"/>
  <axis xyz="1.0 0.000898 0.0"/>
</joint>

<joint name="Revolute_3" type="revolute">
  <origin xyz="0.034861 -0.011969 0.43175" rpy="0 0 0"/>
  <parent link="link2_1"/>
  <child link="link3_1"/>
  <axis xyz="-0.000898 1.0 0.0"/>
  <limit upper="1.570796" lower="-1.570796" effort="100" velocity="100"/>
</joint>

</robot>
