<?xml version="1.0" ?>
<!-- =================================================================================== -->
<!-- |    This document was autogenerated by xacro from dual_arm.urdf.xacro            | -->
<!-- |    EDITING THIS FILE BY HAND IS NOT RECOMMENDED                                 | -->
<!-- =================================================================================== -->
<robot name="dual_arm">
  <material name="silver_default">
    <color rgba="0.700 0.700 0.700 1.000"/>
  </material>
  <material name="steel_satin">
    <color rgba="0.6274509803921569 0.6274509803921569 0.6274509803921569 1.0"/>
  </material>
  <material name="opaque02550">
    <color rgba="0.0 1.0 0.0 1.0"/>
  </material>
  <material name="opaque115115115">
    <color rgba="0.45098039215686275 0.45098039215686275 0.45098039215686275 1.0"/>
  </material>
  <!-- Create the world link -->
  <link name="world"/>
  <!-- Create base link for this arm instance -->
  <link name="left_base_link">
    <inertial>
      <origin rpy="0 0 0" xyz="-0.040820856158367766 0.00036104809684655377 0.015213618835662102"/>
      <mass value="0.700086994811545"/>
      <inertia ixx="0.001733" ixy="1.7e-05" ixz="-2.5e-05" iyy="0.002626" iyz="-4e-06" izz="0.004024"/>
    </inertial>
    <visual>
      <origin rpy="0 0 0" xyz="0 0 0"/>
      <geometry>
        <mesh filename="package://urdf_0816_description/meshes/base_link.stl" scale="0.001 0.001 0.001"/>
      </geometry>
      <material name="steel_satin"/>
    </visual>
    <collision>
      <origin rpy="0 0 0" xyz="0 0 0"/>
      <geometry>
        <mesh filename="package://urdf_0816_description/meshes/base_link.stl" scale="0.001 0.001 0.001"/>
      </geometry>
    </collision>
  </link>
  <!-- Connect to world -->
  <joint name="left_base_joint" type="fixed">
    <origin rpy="0 0 0" xyz="0 0 0"/>
    <parent link="world"/>
    <child link="left_base_link"/>
  </joint>
  <!-- Create all the links and joints for this arm instance -->
  <link name="left_link1_1">
    <inertial>
      <origin rpy="0 0 0" xyz="-0.00010633595242580096 0.00020725329457724776 0.026966319767860035"/>
      <mass value="0.28442007333799074"/>
      <inertia ixx="0.000333" ixy="0.0" ixz="-1e-06" iyy="0.000325" iyz="-2e-06" izz="0.000378"/>
    </inertial>
    <visual>
      <origin rpy="0 0 0" xyz="0.0 -0.0 -0.0555"/>
      <geometry>
        <mesh filename="package://urdf_0816_description/meshes/link1_1.stl" scale="0.001 0.001 0.001"/>
      </geometry>
      <material name="silver_default"/>
    </visual>
    <collision>
      <origin rpy="0 0 0" xyz="0.0 -0.0 -0.0555"/>
      <geometry>
        <mesh filename="package://urdf_0816_description/meshes/link1_1.stl" scale="0.001 0.001 0.001"/>
      </geometry>
    </collision>
  </link>
  <link name="left_link2_1">
    <inertial>
      <origin rpy="0 0 0" xyz="0.0060522563742429385 -0.03069852838470896 0.26309687039061297"/>
      <mass value="2.088012841774827"/>
      <inertia ixx="0.049506" ixy="6.4e-05" ixz="-0.00211" iyy="0.049552" iyz="0.00105" izz="0.000925"/>
    </inertial>
    <visual>
      <origin rpy="0 0 0" xyz="3.7e-05 -0.024464 -0.12355"/>
      <geometry>
        <mesh filename="package://urdf_0816_description/meshes/link2_1.stl" scale="0.001 0.001 0.001"/>
      </geometry>
      <material name="silver_default"/>
    </visual>
    <collision>
      <origin rpy="0 0 0" xyz="3.7e-05 -0.024464 -0.12355"/>
      <geometry>
        <mesh filename="package://urdf_0816_description/meshes/link2_1.stl" scale="0.001 0.001 0.001"/>
      </geometry>
    </collision>
  </link>
  <link name="left_link3_1">
    <inertial>
      <origin rpy="0 0 0" xyz="0.19536238170651474 -0.019556966486173572 0.00017773410978028092"/>
      <mass value="1.722735495745173"/>
      <inertia ixx="0.000514" ixy="-0.001219" ixz="5.5e-05" iyy="0.031424" iyz="1e-06" izz="0.03162"/>
    </inertial>
    <visual>
      <origin rpy="0 0 0" xyz="-0.034824 -0.012495 -0.5553"/>
      <geometry>
        <mesh filename="package://urdf_0816_description/meshes/link3_1.stl" scale="0.001 0.001 0.001"/>
      </geometry>
      <material name="silver_default"/>
    </visual>
    <collision>
      <origin rpy="0 0 0" xyz="-0.034824 -0.012495 -0.5553"/>
      <geometry>
        <mesh filename="package://urdf_0816_description/meshes/link3_1.stl" scale="0.001 0.001 0.001"/>
      </geometry>
    </collision>
  </link>
  <link name="left_link4_1">
    <inertial>
      <origin rpy="0 0 0" xyz="0.04200033140116871 0.00507003235961316 -1.2073697562842156e-06"/>
      <mass value="0.828744250174943"/>
      <inertia ixx="0.00023" ixy="9.5e-05" ixz="-0.0" iyy="0.000619" iyz="0.0" izz="0.000688"/>
    </inertial>
    <visual>
      <origin rpy="0 0 0" xyz="-0.455435 -0.000288 -0.5552"/>
      <geometry>
        <mesh filename="package://urdf_0816_description/meshes/link4_1.stl" scale="0.001 0.001 0.001"/>
      </geometry>
      <material name="silver_default"/>
    </visual>
    <collision>
      <origin rpy="0 0 0" xyz="-0.455435 -0.000288 -0.5552"/>
      <geometry>
        <mesh filename="package://urdf_0816_description/meshes/link4_1.stl" scale="0.001 0.001 0.001"/>
      </geometry>
    </collision>
  </link>
  <link name="left_link5_1">
    <inertial>
      <origin rpy="0 0 0" xyz="0.011649390529319126 -0.018561235276543478 -0.04427731409723035"/>
      <mass value="0.149123060567995"/>
      <inertia ixx="4.1e-05" ixy="0.0" ixz="3e-06" iyy="4.6e-05" iyz="-1e-06" izz="4.4e-05"/>
    </inertial>
    <visual>
      <origin rpy="0 0 0" xyz="-0.534018 -0.019258 -0.5552"/>
      <geometry>
        <mesh filename="package://urdf_0816_description/meshes/link5_1.stl" scale="0.001 0.001 0.001"/>
      </geometry>
      <material name="silver_default"/>
    </visual>
    <collision>
      <origin rpy="0 0 0" xyz="-0.534018 -0.019258 -0.5552"/>
      <geometry>
        <mesh filename="package://urdf_0816_description/meshes/link5_1.stl" scale="0.001 0.001 0.001"/>
      </geometry>
    </collision>
  </link>
  <link name="left_link6_1">
    <inertial>
      <origin rpy="0 0 0" xyz="1.0851645860010528e-05 -0.011072592980630363 -0.021361276335835733"/>
      <mass value="0.4351295137369132"/>
      <inertia ixx="0.000158" ixy="-0.0" ixz="-0.0" iyy="0.000105" iyz="-6e-06" izz="0.000113"/>
    </inertial>
    <visual>
      <origin rpy="0 0 0" xyz="-0.534035 -0.000358 -0.4904"/>
      <geometry>
        <mesh filename="package://urdf_0816_description/meshes/link6_1.stl" scale="0.001 0.001 0.001"/>
      </geometry>
      <material name="silver_default"/>
    </visual>
    <collision>
      <origin rpy="0 0 0" xyz="-0.534035 -0.000358 -0.4904"/>
      <geometry>
        <mesh filename="package://urdf_0816_description/meshes/link6_1.stl" scale="0.001 0.001 0.001"/>
      </geometry>
    </collision>
  </link>
  <link name="left_EndEffector_1">
    <inertial>
      <origin rpy="0 0 0" xyz="4.291544277090775e-05 -0.0036152140147807737 0.004889155227827402"/>
      <mass value="0.2999455316821713"/>
      <inertia ixx="0.000109" ixy="-0.0" ixz="-0.0" iyy="0.000236" iyz="2e-06" izz="0.000277"/>
    </inertial>
    <visual>
      <origin rpy="0 0 0" xyz="-0.533985 -0.000358 -0.4454"/>
      <geometry>
        <mesh filename="package://urdf_0816_description/meshes/EndEffector_1.stl" scale="0.001 0.001 0.001"/>
      </geometry>
      <material name="opaque02550"/>
    </visual>
    <collision>
      <origin rpy="0 0 0" xyz="-0.533985 -0.000358 -0.4454"/>
      <geometry>
        <mesh filename="package://urdf_0816_description/meshes/EndEffector_1.stl" scale="0.001 0.001 0.001"/>
      </geometry>
    </collision>
  </link>
  <link name="left_left_finger_1">
    <inertial>
      <origin rpy="0 0 0" xyz="0.010602170828002466 -2.819158263641687e-05 -0.03403902699335176"/>
      <mass value="0.30761816326804103"/>
      <inertia ixx="0.000538" ixy="0.0" ixz="3.9e-05" iyy="0.000254" iyz="-0.0" izz="0.000321"/>
    </inertial>
    <visual>
      <origin rpy="0 0 0" xyz="-0.478985 -0.000286 -0.4374"/>
      <geometry>
        <mesh filename="package://urdf_0816_description/meshes/left_finger_1.stl" scale="0.001 0.001 0.001"/>
      </geometry>
      <material name="steel_satin"/>
    </visual>
    <collision>
      <origin rpy="0 0 0" xyz="-0.478985 -0.000286 -0.4374"/>
      <geometry>
        <mesh filename="package://urdf_0816_description/meshes/left_finger_1.stl" scale="0.001 0.001 0.001"/>
      </geometry>
    </collision>
  </link>
  <link name="left_right_finger_1">
    <inertial>
      <origin rpy="0 0 0" xyz="-0.010602105454361022 -4.707945734816726e-05 -0.034038644156227704"/>
      <mass value="0.3076182712077128"/>
      <inertia ixx="0.000538" ixy="0.0" ixz="-3.9e-05" iyy="0.000254" iyz="-0.0" izz="0.000321"/>
    </inertial>
    <visual>
      <origin rpy="0 0 0" xyz="-0.588985 -0.000431 -0.4374"/>
      <geometry>
        <mesh filename="package://urdf_0816_description/meshes/right_finger_1.stl" scale="0.001 0.001 0.001"/>
      </geometry>
      <material name="steel_satin"/>
    </visual>
    <collision>
      <origin rpy="0 0 0" xyz="-0.588985 -0.000431 -0.4374"/>
      <geometry>
        <mesh filename="package://urdf_0816_description/meshes/right_finger_1.stl" scale="0.001 0.001 0.001"/>
      </geometry>
    </collision>
  </link>
  <!-- Joints for this arm instance -->
  <joint name="left_Revolute_1" type="continuous">
    <origin rpy="0 0 1.57" xyz="0.0 0.0 0.0555"/>
    <parent link="left_base_link"/>
    <child link="left_link1_1"/>
    <axis xyz="-0.0 0.0 1.0"/>
  </joint>
  <joint name="left_Revolute_2" type="revolute">
    <origin rpy="0 0 0" xyz="-3.7e-05 0.024464 0.06805"/>
    <parent link="left_link1_1"/>
    <child link="left_link2_1"/>
    <axis xyz="-0.000898 1.0 -0.0"/>
    <limit effort="100" lower="-1.570796" upper="1.570796" velocity="100"/>
  </joint>
  <joint name="left_Revolute_3" type="revolute">
    <origin rpy="0 0 0" xyz="0.034861 -0.011969 0.43175"/>
    <parent link="left_link2_1"/>
    <child link="left_link3_1"/>
    <axis xyz="-0.000898 1.0 0.0"/>
    <limit effort="100" lower="-1.570796" upper="3.14159265359" velocity="100"/>
  </joint>
  <joint name="left_Revolute_4" type="continuous">
    <origin rpy="0 0 0" xyz="0.420611 -0.012207 -0.0001"/>
    <parent link="left_link3_1"/>
    <child link="left_link4_1"/>
    <axis xyz="1.0 0.000898 0.0"/>
  </joint>
  <joint name="left_Revolute_5" type="continuous">
    <origin rpy="0 0 0" xyz="0.078583 0.01897 0.0"/>
    <parent link="left_link4_1"/>
    <child link="left_link5_1"/>
    <axis xyz="-0.000898 1.0 0.0"/>
  </joint>
  <joint name="left_Revolute_6" type="continuous">
    <origin rpy="0 0 0" xyz="1.7e-05 -0.0189 -0.0648"/>
    <parent link="left_link5_1"/>
    <child link="left_link6_1"/>
    <axis xyz="0.0 0.0 -1.0"/>
  </joint>
  <joint name="left_Rigid_7" type="fixed">
    <origin rpy="0 0 0" xyz="-5e-05 0.0 -0.045"/>
    <parent link="left_link6_1"/>
    <child link="left_EndEffector_1"/>
  </joint>
  <joint name="left_Slider_1" type="prismatic">
    <origin rpy="0 0 0" xyz="0.055 7.3e-05 -0.008"/>
    <parent link="left_EndEffector_1"/>
    <child link="left_right_finger_1"/>
    <axis xyz="-1.0 -0.000898 -0.0"/>
    <limit effort="100" lower="0.0" upper="0.024" velocity="100"/>
  </joint>
  <joint name="left_Slider_2" type="prismatic">
    <origin rpy="0 0 0" xyz="-0.055 -7.2e-05 -0.008"/>
    <parent link="left_EndEffector_1"/>
    <child link="left_left_finger_1"/>
    <axis xyz="-1.0 -0.000898 -0.0"/>
    <limit effort="100" lower="-0.024" upper="0.0" velocity="100"/>
  </joint>
  <!-- Transmissions for this arm instance -->
  <transmission name="left_Revolute_1_tran">
    <type>transmission_interface/SimpleTransmission</type>
    <joint name="left_Revolute_1">
      <hardwareInterface>hardware_interface/EffortJointInterface</hardwareInterface>
    </joint>
    <actuator name="left_Revolute_1_actr">
      <hardwareInterface>hardware_interface/EffortJointInterface</hardwareInterface>
      <mechanicalReduction>1</mechanicalReduction>
    </actuator>
  </transmission>
  <transmission name="left_Revolute_2_tran">
    <type>transmission_interface/SimpleTransmission</type>
    <joint name="left_Revolute_2">
      <hardwareInterface>hardware_interface/EffortJointInterface</hardwareInterface>
    </joint>
    <actuator name="left_Revolute_2_actr">
      <hardwareInterface>hardware_interface/EffortJointInterface</hardwareInterface>
      <mechanicalReduction>1</mechanicalReduction>
    </actuator>
  </transmission>
  <transmission name="left_Revolute_3_tran">
    <type>transmission_interface/SimpleTransmission</type>
    <joint name="left_Revolute_3">
      <hardwareInterface>hardware_interface/EffortJointInterface</hardwareInterface>
    </joint>
    <actuator name="left_Revolute_3_actr">
      <hardwareInterface>hardware_interface/EffortJointInterface</hardwareInterface>
      <mechanicalReduction>1</mechanicalReduction>
    </actuator>
  </transmission>
  <transmission name="left_Revolute_4_tran">
    <type>transmission_interface/SimpleTransmission</type>
    <joint name="left_Revolute_4">
      <hardwareInterface>hardware_interface/EffortJointInterface</hardwareInterface>
    </joint>
    <actuator name="left_Revolute_4_actr">
      <hardwareInterface>hardware_interface/EffortJointInterface</hardwareInterface>
      <mechanicalReduction>1</mechanicalReduction>
    </actuator>
  </transmission>
  <transmission name="left_Revolute_5_tran">
    <type>transmission_interface/SimpleTransmission</type>
    <joint name="left_Revolute_5">
      <hardwareInterface>hardware_interface/EffortJointInterface</hardwareInterface>
    </joint>
    <actuator name="left_Revolute_5_actr">
      <hardwareInterface>hardware_interface/EffortJointInterface</hardwareInterface>
      <mechanicalReduction>1</mechanicalReduction>
    </actuator>
  </transmission>
  <transmission name="left_Revolute_6_tran">
    <type>transmission_interface/SimpleTransmission</type>
    <joint name="left_Revolute_6">
      <hardwareInterface>hardware_interface/EffortJointInterface</hardwareInterface>
    </joint>
    <actuator name="left_Revolute_6_actr">
      <hardwareInterface>hardware_interface/EffortJointInterface</hardwareInterface>
      <mechanicalReduction>1</mechanicalReduction>
    </actuator>
  </transmission>
  <transmission name="left_Slider_1_tran">
    <type>transmission_interface/SimpleTransmission</type>
    <joint name="left_Slider_1">
      <hardwareInterface>hardware_interface/EffortJointInterface</hardwareInterface>
    </joint>
    <actuator name="left_Slider_1_actr">
      <hardwareInterface>hardware_interface/EffortJointInterface</hardwareInterface>
      <mechanicalReduction>1</mechanicalReduction>
    </actuator>
  </transmission>
  <transmission name="left_Slider_2_tran">
    <type>transmission_interface/SimpleTransmission</type>
    <joint name="left_Slider_2">
      <hardwareInterface>hardware_interface/EffortJointInterface</hardwareInterface>
    </joint>
    <actuator name="left_Slider_2_actr">
      <hardwareInterface>hardware_interface/EffortJointInterface</hardwareInterface>
      <mechanicalReduction>1</mechanicalReduction>
    </actuator>
  </transmission>
  <!-- ROS2 Control for this arm instance -->
  <ros2_control name="left_arm" type="system">
    <hardware>
      <plugin>mock_components/GenericSystem</plugin>
    </hardware>
    <joint name="left_Revolute_1">
      <command_interface name="position"/>
      <state_interface name="position"/>
      <state_interface name="velocity"/>
    </joint>
    <joint name="left_Revolute_2">
      <command_interface name="position"/>
      <state_interface name="position"/>
      <state_interface name="velocity"/>
    </joint>
    <joint name="left_Revolute_3">
      <command_interface name="position"/>
      <state_interface name="position"/>
      <state_interface name="velocity"/>
    </joint>
    <joint name="left_Revolute_4">
      <command_interface name="position"/>
      <state_interface name="position"/>
      <state_interface name="velocity"/>
    </joint>
    <joint name="left_Revolute_5">
      <command_interface name="position"/>
      <state_interface name="position"/>
      <state_interface name="velocity"/>
    </joint>
    <joint name="left_Revolute_6">
      <command_interface name="position"/>
      <state_interface name="position"/>
      <state_interface name="velocity"/>
    </joint>
    <joint name="left_Slider_1">
      <command_interface name="position"/>
      <state_interface name="position"/>
      <state_interface name="velocity"/>
    </joint>
    <joint name="left_Slider_2">
      <command_interface name="position"/>
      <state_interface name="position"/>
      <state_interface name="velocity"/>
    </joint>
  </ros2_control>
  <!-- Create base link for this arm instance -->
  <link name="right_base_link">
    <inertial>
      <origin rpy="0 0 0" xyz="-0.040820856158367766 0.00036104809684655377 0.015213618835662102"/>
      <mass value="0.700086994811545"/>
      <inertia ixx="0.001733" ixy="1.7e-05" ixz="-2.5e-05" iyy="0.002626" iyz="-4e-06" izz="0.004024"/>
    </inertial>
    <visual>
      <origin rpy="0 0 0" xyz="0 0 0"/>
      <geometry>
        <mesh filename="package://urdf_0816_description/meshes/base_link.stl" scale="0.001 0.001 0.001"/>
      </geometry>
      <material name="steel_satin"/>
    </visual>
    <collision>
      <origin rpy="0 0 0" xyz="0 0 0"/>
      <geometry>
        <mesh filename="package://urdf_0816_description/meshes/base_link.stl" scale="0.001 0.001 0.001"/>
      </geometry>
    </collision>
  </link>
  <!-- Connect to world -->
  <joint name="right_base_joint" type="fixed">
    <origin rpy="0 0 0" xyz="0 -0.359 0"/>
    <parent link="world"/>
    <child link="right_base_link"/>
  </joint>
  <!-- Create all the links and joints for this arm instance -->
  <link name="right_link1_1">
    <inertial>
      <origin rpy="0 0 0" xyz="-0.00010633595242580096 0.00020725329457724776 0.026966319767860035"/>
      <mass value="0.28442007333799074"/>
      <inertia ixx="0.000333" ixy="0.0" ixz="-1e-06" iyy="0.000325" iyz="-2e-06" izz="0.000378"/>
    </inertial>
    <visual>
      <origin rpy="0 0 0" xyz="0.0 -0.0 -0.0555"/>
      <geometry>
        <mesh filename="package://urdf_0816_description/meshes/link1_1.stl" scale="0.001 0.001 0.001"/>
      </geometry>
      <material name="silver_default"/>
    </visual>
    <collision>
      <origin rpy="0 0 0" xyz="0.0 -0.0 -0.0555"/>
      <geometry>
        <mesh filename="package://urdf_0816_description/meshes/link1_1.stl" scale="0.001 0.001 0.001"/>
      </geometry>
    </collision>
  </link>
  <link name="right_link2_1">
    <inertial>
      <origin rpy="0 0 0" xyz="0.0060522563742429385 -0.03069852838470896 0.26309687039061297"/>
      <mass value="2.088012841774827"/>
      <inertia ixx="0.049506" ixy="6.4e-05" ixz="-0.00211" iyy="0.049552" iyz="0.00105" izz="0.000925"/>
    </inertial>
    <visual>
      <origin rpy="0 0 0" xyz="3.7e-05 -0.024464 -0.12355"/>
      <geometry>
        <mesh filename="package://urdf_0816_description/meshes/link2_1.stl" scale="0.001 0.001 0.001"/>
      </geometry>
      <material name="silver_default"/>
    </visual>
    <collision>
      <origin rpy="0 0 0" xyz="3.7e-05 -0.024464 -0.12355"/>
      <geometry>
        <mesh filename="package://urdf_0816_description/meshes/link2_1.stl" scale="0.001 0.001 0.001"/>
      </geometry>
    </collision>
  </link>
  <link name="right_link3_1">
    <inertial>
      <origin rpy="0 0 0" xyz="0.19536238170651474 -0.019556966486173572 0.00017773410978028092"/>
      <mass value="1.722735495745173"/>
      <inertia ixx="0.000514" ixy="-0.001219" ixz="5.5e-05" iyy="0.031424" iyz="1e-06" izz="0.03162"/>
    </inertial>
    <visual>
      <origin rpy="0 0 0" xyz="-0.034824 -0.012495 -0.5553"/>
      <geometry>
        <mesh filename="package://urdf_0816_description/meshes/link3_1.stl" scale="0.001 0.001 0.001"/>
      </geometry>
      <material name="silver_default"/>
    </visual>
    <collision>
      <origin rpy="0 0 0" xyz="-0.034824 -0.012495 -0.5553"/>
      <geometry>
        <mesh filename="package://urdf_0816_description/meshes/link3_1.stl" scale="0.001 0.001 0.001"/>
      </geometry>
    </collision>
  </link>
  <link name="right_link4_1">
    <inertial>
      <origin rpy="0 0 0" xyz="0.04200033140116871 0.00507003235961316 -1.2073697562842156e-06"/>
      <mass value="0.828744250174943"/>
      <inertia ixx="0.00023" ixy="9.5e-05" ixz="-0.0" iyy="0.000619" iyz="0.0" izz="0.000688"/>
    </inertial>
    <visual>
      <origin rpy="0 0 0" xyz="-0.455435 -0.000288 -0.5552"/>
      <geometry>
        <mesh filename="package://urdf_0816_description/meshes/link4_1.stl" scale="0.001 0.001 0.001"/>
      </geometry>
      <material name="silver_default"/>
    </visual>
    <collision>
      <origin rpy="0 0 0" xyz="-0.455435 -0.000288 -0.5552"/>
      <geometry>
        <mesh filename="package://urdf_0816_description/meshes/link4_1.stl" scale="0.001 0.001 0.001"/>
      </geometry>
    </collision>
  </link>
  <link name="right_link5_1">
    <inertial>
      <origin rpy="0 0 0" xyz="0.011649390529319126 -0.018561235276543478 -0.04427731409723035"/>
      <mass value="0.149123060567995"/>
      <inertia ixx="4.1e-05" ixy="0.0" ixz="3e-06" iyy="4.6e-05" iyz="-1e-06" izz="4.4e-05"/>
    </inertial>
    <visual>
      <origin rpy="0 0 0" xyz="-0.534018 -0.019258 -0.5552"/>
      <geometry>
        <mesh filename="package://urdf_0816_description/meshes/link5_1.stl" scale="0.001 0.001 0.001"/>
      </geometry>
      <material name="silver_default"/>
    </visual>
    <collision>
      <origin rpy="0 0 0" xyz="-0.534018 -0.019258 -0.5552"/>
      <geometry>
        <mesh filename="package://urdf_0816_description/meshes/link5_1.stl" scale="0.001 0.001 0.001"/>
      </geometry>
    </collision>
  </link>
  <link name="right_link6_1">
    <inertial>
      <origin rpy="0 0 0" xyz="1.0851645860010528e-05 -0.011072592980630363 -0.021361276335835733"/>
      <mass value="0.4351295137369132"/>
      <inertia ixx="0.000158" ixy="-0.0" ixz="-0.0" iyy="0.000105" iyz="-6e-06" izz="0.000113"/>
    </inertial>
    <visual>
      <origin rpy="0 0 0" xyz="-0.534035 -0.000358 -0.4904"/>
      <geometry>
        <mesh filename="package://urdf_0816_description/meshes/link6_1.stl" scale="0.001 0.001 0.001"/>
      </geometry>
      <material name="silver_default"/>
    </visual>
    <collision>
      <origin rpy="0 0 0" xyz="-0.534035 -0.000358 -0.4904"/>
      <geometry>
        <mesh filename="package://urdf_0816_description/meshes/link6_1.stl" scale="0.001 0.001 0.001"/>
      </geometry>
    </collision>
  </link>
  <link name="right_EndEffector_1">
    <inertial>
      <origin rpy="0 0 0" xyz="4.291544277090775e-05 -0.0036152140147807737 0.004889155227827402"/>
      <mass value="0.2999455316821713"/>
      <inertia ixx="0.000109" ixy="-0.0" ixz="-0.0" iyy="0.000236" iyz="2e-06" izz="0.000277"/>
    </inertial>
    <visual>
      <origin rpy="0 0 0" xyz="-0.533985 -0.000358 -0.4454"/>
      <geometry>
        <mesh filename="package://urdf_0816_description/meshes/EndEffector_1.stl" scale="0.001 0.001 0.001"/>
      </geometry>
      <material name="opaque02550"/>
    </visual>
    <collision>
      <origin rpy="0 0 0" xyz="-0.533985 -0.000358 -0.4454"/>
      <geometry>
        <mesh filename="package://urdf_0816_description/meshes/EndEffector_1.stl" scale="0.001 0.001 0.001"/>
      </geometry>
    </collision>
  </link>
  <link name="right_left_finger_1">
    <inertial>
      <origin rpy="0 0 0" xyz="0.010602170828002466 -2.819158263641687e-05 -0.03403902699335176"/>
      <mass value="0.30761816326804103"/>
      <inertia ixx="0.000538" ixy="0.0" ixz="3.9e-05" iyy="0.000254" iyz="-0.0" izz="0.000321"/>
    </inertial>
    <visual>
      <origin rpy="0 0 0" xyz="-0.478985 -0.000286 -0.4374"/>
      <geometry>
        <mesh filename="package://urdf_0816_description/meshes/left_finger_1.stl" scale="0.001 0.001 0.001"/>
      </geometry>
      <material name="steel_satin"/>
    </visual>
    <collision>
      <origin rpy="0 0 0" xyz="-0.478985 -0.000286 -0.4374"/>
      <geometry>
        <mesh filename="package://urdf_0816_description/meshes/left_finger_1.stl" scale="0.001 0.001 0.001"/>
      </geometry>
    </collision>
  </link>
  <link name="right_right_finger_1">
    <inertial>
      <origin rpy="0 0 0" xyz="-0.010602105454361022 -4.707945734816726e-05 -0.034038644156227704"/>
      <mass value="0.3076182712077128"/>
      <inertia ixx="0.000538" ixy="0.0" ixz="-3.9e-05" iyy="0.000254" iyz="-0.0" izz="0.000321"/>
    </inertial>
    <visual>
      <origin rpy="0 0 0" xyz="-0.588985 -0.000431 -0.4374"/>
      <geometry>
        <mesh filename="package://urdf_0816_description/meshes/right_finger_1.stl" scale="0.001 0.001 0.001"/>
      </geometry>
      <material name="steel_satin"/>
    </visual>
    <collision>
      <origin rpy="0 0 0" xyz="-0.588985 -0.000431 -0.4374"/>
      <geometry>
        <mesh filename="package://urdf_0816_description/meshes/right_finger_1.stl" scale="0.001 0.001 0.001"/>
      </geometry>
    </collision>
  </link>
  <!-- Joints for this arm instance -->
  <joint name="right_Revolute_1" type="continuous">
    <origin rpy="0 0 -1.57" xyz="0.0 0.0 0.0555"/>
    <parent link="right_base_link"/>
    <child link="right_link1_1"/>
    <axis xyz="-0.0 0.0 1.0"/>
  </joint>
  <joint name="right_Revolute_2" type="revolute">
    <origin rpy="0 0 0" xyz="-3.7e-05 0.024464 0.06805"/>
    <parent link="right_link1_1"/>
    <child link="right_link2_1"/>
    <axis xyz="-0.000898 1.0 -0.0"/>
    <limit effort="100" lower="-1.570796" upper="1.570796" velocity="100"/>
  </joint>
  <joint name="right_Revolute_3" type="revolute">
    <origin rpy="0 0 0" xyz="0.034861 -0.011969 0.43175"/>
    <parent link="right_link2_1"/>
    <child link="right_link3_1"/>
    <axis xyz="-0.000898 1.0 0.0"/>
    <limit effort="100" lower="-1.570796" upper="3.14159265359" velocity="100"/>
  </joint>
  <joint name="right_Revolute_4" type="continuous">
    <origin rpy="0 0 0" xyz="0.420611 -0.012207 -0.0001"/>
    <parent link="right_link3_1"/>
    <child link="right_link4_1"/>
    <axis xyz="1.0 0.000898 0.0"/>
  </joint>
  <joint name="right_Revolute_5" type="continuous">
    <origin rpy="0 0 0" xyz="0.078583 0.01897 0.0"/>
    <parent link="right_link4_1"/>
    <child link="right_link5_1"/>
    <axis xyz="-0.000898 1.0 0.0"/>
  </joint>
  <joint name="right_Revolute_6" type="continuous">
    <origin rpy="0 0 0" xyz="1.7e-05 -0.0189 -0.0648"/>
    <parent link="right_link5_1"/>
    <child link="right_link6_1"/>
    <axis xyz="0.0 0.0 -1.0"/>
  </joint>
  <joint name="right_Rigid_7" type="fixed">
    <origin rpy="0 0 0" xyz="-5e-05 0.0 -0.045"/>
    <parent link="right_link6_1"/>
    <child link="right_EndEffector_1"/>
  </joint>
  <joint name="right_Slider_1" type="prismatic">
    <origin rpy="0 0 0" xyz="0.055 7.3e-05 -0.008"/>
    <parent link="right_EndEffector_1"/>
    <child link="right_right_finger_1"/>
    <axis xyz="-1.0 -0.000898 -0.0"/>
    <limit effort="100" lower="0.0" upper="0.024" velocity="100"/>
  </joint>
  <joint name="right_Slider_2" type="prismatic">
    <origin rpy="0 0 0" xyz="-0.055 -7.2e-05 -0.008"/>
    <parent link="right_EndEffector_1"/>
    <child link="right_left_finger_1"/>
    <axis xyz="-1.0 -0.000898 -0.0"/>
    <limit effort="100" lower="-0.024" upper="0.0" velocity="100"/>
  </joint>
  <!-- Transmissions for this arm instance -->
  <transmission name="right_Revolute_1_tran">
    <type>transmission_interface/SimpleTransmission</type>
    <joint name="right_Revolute_1">
      <hardwareInterface>hardware_interface/EffortJointInterface</hardwareInterface>
    </joint>
    <actuator name="right_Revolute_1_actr">
      <hardwareInterface>hardware_interface/EffortJointInterface</hardwareInterface>
      <mechanicalReduction>1</mechanicalReduction>
    </actuator>
  </transmission>
  <transmission name="right_Revolute_2_tran">
    <type>transmission_interface/SimpleTransmission</type>
    <joint name="right_Revolute_2">
      <hardwareInterface>hardware_interface/EffortJointInterface</hardwareInterface>
    </joint>
    <actuator name="right_Revolute_2_actr">
      <hardwareInterface>hardware_interface/EffortJointInterface</hardwareInterface>
      <mechanicalReduction>1</mechanicalReduction>
    </actuator>
  </transmission>
  <transmission name="right_Revolute_3_tran">
    <type>transmission_interface/SimpleTransmission</type>
    <joint name="right_Revolute_3">
      <hardwareInterface>hardware_interface/EffortJointInterface</hardwareInterface>
    </joint>
    <actuator name="right_Revolute_3_actr">
      <hardwareInterface>hardware_interface/EffortJointInterface</hardwareInterface>
      <mechanicalReduction>1</mechanicalReduction>
    </actuator>
  </transmission>
  <transmission name="right_Revolute_4_tran">
    <type>transmission_interface/SimpleTransmission</type>
    <joint name="right_Revolute_4">
      <hardwareInterface>hardware_interface/EffortJointInterface</hardwareInterface>
    </joint>
    <actuator name="right_Revolute_4_actr">
      <hardwareInterface>hardware_interface/EffortJointInterface</hardwareInterface>
      <mechanicalReduction>1</mechanicalReduction>
    </actuator>
  </transmission>
  <transmission name="right_Revolute_5_tran">
    <type>transmission_interface/SimpleTransmission</type>
    <joint name="right_Revolute_5">
      <hardwareInterface>hardware_interface/EffortJointInterface</hardwareInterface>
    </joint>
    <actuator name="right_Revolute_5_actr">
      <hardwareInterface>hardware_interface/EffortJointInterface</hardwareInterface>
      <mechanicalReduction>1</mechanicalReduction>
    </actuator>
  </transmission>
  <transmission name="right_Revolute_6_tran">
    <type>transmission_interface/SimpleTransmission</type>
    <joint name="right_Revolute_6">
      <hardwareInterface>hardware_interface/EffortJointInterface</hardwareInterface>
    </joint>
    <actuator name="right_Revolute_6_actr">
      <hardwareInterface>hardware_interface/EffortJointInterface</hardwareInterface>
      <mechanicalReduction>1</mechanicalReduction>
    </actuator>
  </transmission>
  <transmission name="right_Slider_1_tran">
    <type>transmission_interface/SimpleTransmission</type>
    <joint name="right_Slider_1">
      <hardwareInterface>hardware_interface/EffortJointInterface</hardwareInterface>
    </joint>
    <actuator name="right_Slider_1_actr">
      <hardwareInterface>hardware_interface/EffortJointInterface</hardwareInterface>
      <mechanicalReduction>1</mechanicalReduction>
    </actuator>
  </transmission>
  <transmission name="right_Slider_2_tran">
    <type>transmission_interface/SimpleTransmission</type>
    <joint name="right_Slider_2">
      <hardwareInterface>hardware_interface/EffortJointInterface</hardwareInterface>
    </joint>
    <actuator name="right_Slider_2_actr">
      <hardwareInterface>hardware_interface/EffortJointInterface</hardwareInterface>
      <mechanicalReduction>1</mechanicalReduction>
    </actuator>
  </transmission>
  <!-- ROS2 Control for this arm instance -->
  <ros2_control name="right_arm" type="system">
    <hardware>
      <plugin>mock_components/GenericSystem</plugin>
    </hardware>
    <joint name="right_Revolute_1">
      <command_interface name="position"/>
      <state_interface name="position"/>
      <state_interface name="velocity"/>
    </joint>
    <joint name="right_Revolute_2">
      <command_interface name="position"/>
      <state_interface name="position"/>
      <state_interface name="velocity"/>
    </joint>
    <joint name="right_Revolute_3">
      <command_interface name="position"/>
      <state_interface name="position"/>
      <state_interface name="velocity"/>
    </joint>
    <joint name="right_Revolute_4">
      <command_interface name="position"/>
      <state_interface name="position"/>
      <state_interface name="velocity"/>
    </joint>
    <joint name="right_Revolute_5">
      <command_interface name="position"/>
      <state_interface name="position"/>
      <state_interface name="velocity"/>
    </joint>
    <joint name="right_Revolute_6">
      <command_interface name="position"/>
      <state_interface name="position"/>
      <state_interface name="velocity"/>
    </joint>
    <joint name="right_Slider_1">
      <command_interface name="position"/>
      <state_interface name="position"/>
      <state_interface name="velocity"/>
    </joint>
    <joint name="right_Slider_2">
      <command_interface name="position"/>
      <state_interface name="position"/>
      <state_interface name="velocity"/>
    </joint>
  </ros2_control>
</robot>
