<?xml version="1.0"?>
<robot xmlns:xacro="http://www.ros.org/wiki/xacro" name="dual_arm">

    <xacro:arg name="initial_positions_file" default="initial_positions.yaml"/>
    <xacro:arg name="use_fake_hardware" default="false"/>
    <xacro:arg name="left_Revolute_1_initial" default="0.0"/>
    <xacro:arg name="left_Revolute_2_initial" default="0.0"/>
    <xacro:arg name="left_Revolute_3_initial" default="0.0"/>
    <xacro:arg name="left_Revolute_4_initial" default="0.0"/>
    <xacro:arg name="left_Revolute_5_initial" default="0.0"/>
    <xacro:arg name="left_Revolute_6_initial" default="0.0"/>
    <xacro:arg name="left_Slider_1_initial" default="0.0"/>
    <xacro:arg name="left_Slider_2_initial" default="0.0"/>
    <xacro:arg name="right_Revolute_1_initial" default="0.0"/>
    <xacro:arg name="right_Revolute_2_initial" default="0.0"/>
    <xacro:arg name="right_Revolute_3_initial" default="0.0"/>
    <xacro:arg name="right_Revolute_4_initial" default="0.0"/>
    <xacro:arg name="right_Revolute_5_initial" default="0.0"/>
    <xacro:arg name="right_Revolute_6_initial" default="0.0"/>
    <xacro:arg name="right_Slider_1_initial" default="0.0"/>
    <xacro:arg name="right_Slider_2_initial" default="0.0"/>
    
    <!-- Joint limits for left arm revolute joints -->
    <xacro:arg name="left_Revolute_1_lower_limit" default="-1.570796"/>
    <xacro:arg name="left_Revolute_1_upper_limit" default="1.570796"/>
    <xacro:arg name="left_Revolute_2_lower_limit" default="-1.570796"/>
    <xacro:arg name="left_Revolute_2_upper_limit" default="1.570796"/>
    <xacro:arg name="left_Revolute_3_lower_limit" default="-1.570796"/>
    <xacro:arg name="left_Revolute_3_upper_limit" default="3.14159265359"/>
    <xacro:arg name="left_Slider_1_lower_limit" default="0.0"/>
    <xacro:arg name="left_Slider_1_upper_limit" default="0.024"/>
    <xacro:arg name="left_Slider_2_lower_limit" default="-0.024"/>
    <xacro:arg name="left_Slider_2_upper_limit" default="0.0"/>
    
    <!-- Joint limits for right arm revolute joints -->
    <xacro:arg name="right_Revolute_1_lower_limit" default="-1.570796"/>
    <xacro:arg name="right_Revolute_1_upper_limit" default="1.570796"/>
    <xacro:arg name="right_Revolute_2_lower_limit" default="-1.570796"/>
    <xacro:arg name="right_Revolute_2_upper_limit" default="1.570796"/>
    <xacro:arg name="right_Revolute_3_lower_limit" default="-1.570796"/>
    <xacro:arg name="right_Revolute_3_upper_limit" default="3.14159265359"/>
    <xacro:arg name="right_Slider_1_lower_limit" default="0.0"/>
    <xacro:arg name="right_Slider_1_upper_limit" default="0.024"/>
    <xacro:arg name="right_Slider_2_lower_limit" default="-0.024"/>
    <xacro:arg name="right_Slider_2_upper_limit" default="0.0"/>
    
    <!-- Left arm origin -->
    <xacro:arg name="left_origin_xyz" default="0 0.2 0"/>
    <xacro:arg name="left_origin_rpy" default="0 0 0"/>
    <!-- Right arm origin -->
    <xacro:arg name="right_origin_xyz" default="0 -0.2 0"/>
    <xacro:arg name="right_origin_rpy" default="0 0 0"/>

    <!-- Import materials from urdf_0816 -->
    <xacro:include filename="$(find urdf_0816_description)/urdf/materials.xacro" />

    <!-- Macro to create an arm with a prefix -->
    <xacro:macro name="arm_instance" params="prefix 
        base_origin_xyz base_origin_rpy
        Revolute_1_xyz Revolute_1_rpy
        Revolute_2_xyz Revolute_2_rpy
        Revolute_3_xyz Revolute_3_rpy
        Revolute_4_xyz Revolute_4_rpy
        Revolute_5_xyz Revolute_5_rpy
        Revolute_6_xyz Revolute_6_rpy
        Rigid_7_xyz Rigid_7_rpy
        Slider_1_xyz Slider_1_rpy
        Slider_2_xyz Slider_2_rpy">
        <!-- Create base link for this arm instance -->
        <link name="${prefix}base_link">
            <inertial>
                <origin rpy="0 0 0" xyz="-0.040820856158367766 0.00036104809684655377 0.015213618835662102"/>
                <mass value="0.700086994811545"/>
                <inertia ixx="0.001733" ixy="1.7e-05" ixz="-2.5e-05" iyy="0.002626" iyz="-4e-06" izz="0.004024"/>
            </inertial>
            <visual>
                <origin rpy="0 0 0" xyz="0 0 0"/>
                <geometry>
                    <mesh filename="package://urdf_0816_description/meshes/base_link.stl" scale="0.001 0.001 0.001"/>
                </geometry>
                <material name="steel_satin"/>
            </visual>
            <collision>
                <origin rpy="0 0 0" xyz="0 0 0"/>
                <geometry>
                    <mesh filename="package://urdf_0816_description/meshes/base_link.stl" scale="0.001 0.001 0.001"/>
                </geometry>
            </collision>
        </link>

        <!-- Connect to world -->
        <joint name="${prefix}base_joint" type="fixed">
            <origin xyz="${base_origin_xyz}" rpy="${base_origin_rpy}"/>
            <parent link="world"/>
            <child link="${prefix}base_link"/>
        </joint>

        <!-- Create all the links and joints for this arm instance -->
        <link name="${prefix}link1_1">
            <inertial>
                <origin rpy="0 0 0" xyz="-0.00010633595242580096 0.00020725329457724776 0.026966319767860035"/>
                <mass value="0.28442007333799074"/>
                <inertia ixx="0.000333" ixy="0.0" ixz="-1e-06" iyy="0.000325" iyz="-2e-06" izz="0.000378"/>
            </inertial>
            <visual>
                <origin rpy="0 0 0" xyz="0.0 -0.0 -0.0555"/>
                <geometry>
                    <mesh filename="package://urdf_0816_description/meshes/link1_1.stl" scale="0.001 0.001 0.001"/>
                </geometry>
                <material name="silver_default"/>
            </visual>
            <collision>
                <origin rpy="0 0 0" xyz="0.0 -0.0 -0.0555"/>
                <geometry>
                    <mesh filename="package://urdf_0816_description/meshes/link1_1.stl" scale="0.001 0.001 0.001"/>
                </geometry>
            </collision>
        </link>

        <link name="${prefix}link2_1">
            <inertial>
                <origin rpy="0 0 0" xyz="0.0060522563742429385 -0.03069852838470896 0.26309687039061297"/>
                <mass value="2.088012841774827"/>
                <inertia ixx="0.049506" ixy="6.4e-05" ixz="-0.00211" iyy="0.049552" iyz="0.00105" izz="0.000925"/>
            </inertial>
            <visual>
                <origin rpy="0 0 0" xyz="3.7e-05 -0.024464 -0.12355"/>
                <geometry>
                    <mesh filename="package://urdf_0816_description/meshes/link2_1.stl" scale="0.001 0.001 0.001"/>
                </geometry>
                <material name="silver_default"/>
            </visual>
            <collision>
                <origin rpy="0 0 0" xyz="3.7e-05 -0.024464 -0.12355"/>
                <geometry>
                    <mesh filename="package://urdf_0816_description/meshes/link2_1.stl" scale="0.001 0.001 0.001"/>
                </geometry>
            </collision>
        </link>

        <link name="${prefix}link3_1">
            <inertial>
                <origin rpy="0 0 0" xyz="0.19536238170651474 -0.019556966486173572 0.00017773410978028092"/>
                <mass value="1.722735495745173"/>
                <inertia ixx="0.000514" ixy="-0.001219" ixz="5.5e-05" iyy="0.031424" iyz="1e-06" izz="0.03162"/>
            </inertial>
            <visual>
                <origin rpy="0 0 0" xyz="-0.034824 -0.012495 -0.5553"/>
                <geometry>
                    <mesh filename="package://urdf_0816_description/meshes/link3_1.stl" scale="0.001 0.001 0.001"/>
                </geometry>
                <material name="silver_default"/>
            </visual>
            <collision>
                <origin rpy="0 0 0" xyz="-0.034824 -0.012495 -0.5553"/>
                <geometry>
                    <mesh filename="package://urdf_0816_description/meshes/link3_1.stl" scale="0.001 0.001 0.001"/>
                </geometry>
            </collision>
        </link>

        <link name="${prefix}link4_1">
            <inertial>
                <origin rpy="0 0 0" xyz="0.04200033140116871 0.00507003235961316 -1.2073697562842156e-06"/>
                <mass value="0.828744250174943"/>
                <inertia ixx="0.00023" ixy="9.5e-05" ixz="-0.0" iyy="0.000619" iyz="0.0" izz="0.000688"/>
            </inertial>
            <visual>
                <origin rpy="0 0 0" xyz="-0.455435 -0.000288 -0.5552"/>
                <geometry>
                    <mesh filename="package://urdf_0816_description/meshes/link4_1.stl" scale="0.001 0.001 0.001"/>
                </geometry>
                <material name="silver_default"/>
            </visual>
            <collision>
                <origin rpy="0 0 0" xyz="-0.455435 -0.000288 -0.5552"/>
                <geometry>
                    <mesh filename="package://urdf_0816_description/meshes/link4_1.stl" scale="0.001 0.001 0.001"/>
                </geometry>
            </collision>
        </link>

        <link name="${prefix}link5_1">
            <inertial>
                <origin rpy="0 0 0" xyz="0.011649390529319126 -0.018561235276543478 -0.04427731409723035"/>
                <mass value="0.149123060567995"/>
                <inertia ixx="4.1e-05" ixy="0.0" ixz="3e-06" iyy="4.6e-05" iyz="-1e-06" izz="4.4e-05"/>
            </inertial>
            <visual>
                <origin rpy="0 0 0" xyz="-0.534018 -0.019258 -0.5552"/>
                <geometry>
                    <mesh filename="package://urdf_0816_description/meshes/link5_1.stl" scale="0.001 0.001 0.001"/>
                </geometry>
                <material name="silver_default"/>
            </visual>
            <collision>
                <origin rpy="0 0 0" xyz="-0.534018 -0.019258 -0.5552"/>
                <geometry>
                    <mesh filename="package://urdf_0816_description/meshes/link5_1.stl" scale="0.001 0.001 0.001"/>
                </geometry>
            </collision>
        </link>

        <link name="${prefix}link6_1">
            <inertial>
                <origin rpy="0 0 0" xyz="1.0851645860010528e-05 -0.011072592980630363 -0.021361276335835733"/>
                <mass value="0.4351295137369132"/>
                <inertia ixx="0.000158" ixy="-0.0" ixz="-0.0" iyy="0.000105" iyz="-6e-06" izz="0.000113"/>
            </inertial>
            <visual>
                <origin rpy="0 0 0" xyz="-0.534035 -0.000358 -0.4904"/>
                <geometry>
                    <mesh filename="package://urdf_0816_description/meshes/link6_1.stl" scale="0.001 0.001 0.001"/>
                </geometry>
                <material name="silver_default"/>
            </visual>
            <collision>
                <origin rpy="0 0 0" xyz="-0.534035 -0.000358 -0.4904"/>
                <geometry>
                    <mesh filename="package://urdf_0816_description/meshes/link6_1.stl" scale="0.001 0.001 0.001"/>
                </geometry>
            </collision>
        </link>

        <link name="${prefix}EndEffector_1">
            <inertial>
                <origin rpy="0 0 0" xyz="4.291544277090775e-05 -0.0036152140147807737 0.004889155227827402"/>
                <mass value="0.2999455316821713"/>
                <inertia ixx="0.000109" ixy="-0.0" ixz="-0.0" iyy="0.000236" iyz="2e-06" izz="0.000277"/>
            </inertial>
            <visual>
                <origin rpy="0 0 0" xyz="-0.533985 -0.000358 -0.4454"/>
                <geometry>
                    <mesh filename="package://urdf_0816_description/meshes/EndEffector_1.stl" scale="0.001 0.001 0.001"/>
                </geometry>
                <material name="opaque02550"/>
            </visual>
            <collision>
                <origin rpy="0 0 0" xyz="-0.533985 -0.000358 -0.4454"/>
                <geometry>
                    <mesh filename="package://urdf_0816_description/meshes/EndEffector_1.stl" scale="0.001 0.001 0.001"/>
                </geometry>
            </collision>
        </link>

        <link name="${prefix}left_finger_1">
            <inertial>
                <origin rpy="0 0 0" xyz="0.010602170828002466 -2.819158263641687e-05 -0.03403902699335176"/>
                <mass value="0.30761816326804103"/>
                <inertia ixx="0.000538" ixy="0.0" ixz="3.9e-05" iyy="0.000254" iyz="-0.0" izz="0.000321"/>
            </inertial>
            <visual>
                <origin rpy="0 0 0" xyz="-0.478985 -0.000286 -0.4374"/>
                <geometry>
                    <mesh filename="package://urdf_0816_description/meshes/left_finger_1.stl" scale="0.001 0.001 0.001"/>
                </geometry>
                <material name="steel_satin"/>
            </visual>
            <collision>
                <origin rpy="0 0 0" xyz="-0.478985 -0.000286 -0.4374"/>
                <geometry>
                    <mesh filename="package://urdf_0816_description/meshes/left_finger_1.stl" scale="0.001 0.001 0.001"/>
                </geometry>
            </collision>
        </link>

        <link name="${prefix}right_finger_1">
            <inertial>
                <origin rpy="0 0 0" xyz="-0.010602105454361022 -4.707945734816726e-05 -0.034038644156227704"/>
                <mass value="0.3076182712077128"/>
                <inertia ixx="0.000538" ixy="0.0" ixz="-3.9e-05" iyy="0.000254" iyz="-0.0" izz="0.000321"/>
            </inertial>
            <visual>
                <origin rpy="0 0 0" xyz="-0.588985 -0.000431 -0.4374"/>
                <geometry>
                    <mesh filename="package://urdf_0816_description/meshes/right_finger_1.stl" scale="0.001 0.001 0.001"/>
                </geometry>
                <material name="steel_satin"/>
            </visual>
            <collision>
                <origin rpy="0 0 0" xyz="-0.588985 -0.000431 -0.4374"/>
                <geometry>
                    <mesh filename="package://urdf_0816_description/meshes/right_finger_1.stl" scale="0.001 0.001 0.001"/>
                </geometry>
            </collision>
        </link>

        <!-- Joints for this arm instance -->
        <joint name="${prefix}Revolute_1" type="revolute">
            <origin rpy="${Revolute_1_rpy}" xyz="${Revolute_1_xyz}"/>
            <parent link="${prefix}base_link"/>
            <child link="${prefix}link1_1"/>
            <axis xyz="-0.0 0.0 1.0"/>
            <limit effort="100" lower="$(arg ${prefix}Revolute_1_lower_limit)" upper="$(arg ${prefix}Revolute_1_upper_limit)" velocity="100"/>
        </joint>
        <joint name="${prefix}Revolute_2" type="revolute">
            <origin rpy="${Revolute_2_rpy}" xyz="${Revolute_2_xyz}"/>
            <parent link="${prefix}link1_1"/>
            <child link="${prefix}link2_1"/>
            <axis xyz="-0.000898 1.0 -0.0"/>
            <limit effort="100" lower="$(arg ${prefix}Revolute_2_lower_limit)" upper="$(arg ${prefix}Revolute_2_upper_limit)" velocity="100"/>
        </joint>
        <joint name="${prefix}Revolute_3" type="revolute">
            <origin rpy="${Revolute_3_rpy}" xyz="${Revolute_3_xyz}"/>
            <parent link="${prefix}link2_1"/>
            <child link="${prefix}link3_1"/>
            <axis xyz="-0.000898 1.0 0.0"/>
            <limit effort="100" lower="$(arg ${prefix}Revolute_3_lower_limit)" upper="$(arg ${prefix}Revolute_3_upper_limit)" velocity="100"/>
        </joint>
        <joint name="${prefix}Revolute_4" type="continuous">
            <origin rpy="${Revolute_4_rpy}" xyz="${Revolute_4_xyz}"/>
            <parent link="${prefix}link3_1"/>
            <child link="${prefix}link4_1"/>
            <axis xyz="1.0 0.000898 0.0"/>
        </joint>
        <joint name="${prefix}Revolute_5" type="continuous">
            <origin rpy="${Revolute_5_rpy}" xyz="${Revolute_5_xyz}"/>
            <parent link="${prefix}link4_1"/>
            <child link="${prefix}link5_1"/>
            <axis xyz="-0.000898 1.0 0.0"/>
        </joint>
        <joint name="${prefix}Revolute_6" type="continuous">
            <origin rpy="${Revolute_6_rpy}" xyz="${Revolute_6_xyz}"/>
            <parent link="${prefix}link5_1"/>
            <child link="${prefix}link6_1"/>
            <axis xyz="0.0 0.0 -1.0"/>
        </joint>
        <joint name="${prefix}Rigid_7" type="fixed">
            <origin rpy="${Rigid_7_rpy}" xyz="${Rigid_7_xyz}"/>
            <parent link="${prefix}link6_1"/>
            <child link="${prefix}EndEffector_1"/>
        </joint>
        <joint name="${prefix}Slider_1" type="prismatic">
            <origin rpy="${Slider_1_rpy}" xyz="${Slider_1_xyz}"/>
            <parent link="${prefix}EndEffector_1"/>
            <child link="${prefix}right_finger_1"/>
            <axis xyz="-1.0 -0.000898 -0.0"/>
            <limit effort="1000000000" lower="$(arg ${prefix}Slider_1_lower_limit)" upper="$(arg ${prefix}Slider_1_upper_limit)" velocity="100"/>
        </joint>
        <joint name="${prefix}Slider_2" type="prismatic">
            <origin rpy="${Slider_2_rpy}" xyz="${Slider_2_xyz}"/>
            <parent link="${prefix}EndEffector_1"/>
            <child link="${prefix}left_finger_1"/>
            <axis xyz="-1.0 -0.000898 -0.0"/>
            <limit effort="1000000000" lower="$(arg ${prefix}Slider_2_lower_limit)" upper="$(arg ${prefix}Slider_2_upper_limit)" velocity="100"/>
        </joint>

        <!-- Transmissions for this arm instance -->
        <transmission name="${prefix}Revolute_1_tran">
            <type>transmission_interface/SimpleTransmission</type>
            <joint name="${prefix}Revolute_1">
                <hardwareInterface>hardware_interface/EffortJointInterface</hardwareInterface>
            </joint>
            <actuator name="${prefix}Revolute_1_actr">
                <hardwareInterface>hardware_interface/EffortJointInterface</hardwareInterface>
                <mechanicalReduction>1</mechanicalReduction>
            </actuator>
        </transmission>
        <transmission name="${prefix}Revolute_2_tran">
            <type>transmission_interface/SimpleTransmission</type>
            <joint name="${prefix}Revolute_2">
                <hardwareInterface>hardware_interface/EffortJointInterface</hardwareInterface>
            </joint>
            <actuator name="${prefix}Revolute_2_actr">
                <hardwareInterface>hardware_interface/EffortJointInterface</hardwareInterface>
                <mechanicalReduction>1</mechanicalReduction>
            </actuator>
        </transmission>
        <transmission name="${prefix}Revolute_3_tran">
            <type>transmission_interface/SimpleTransmission</type>
            <joint name="${prefix}Revolute_3">
                <hardwareInterface>hardware_interface/EffortJointInterface</hardwareInterface>
            </joint>
            <actuator name="${prefix}Revolute_3_actr">
                <hardwareInterface>hardware_interface/EffortJointInterface</hardwareInterface>
                <mechanicalReduction>1</mechanicalReduction>
            </actuator>
        </transmission>
        <transmission name="${prefix}Revolute_4_tran">
            <type>transmission_interface/SimpleTransmission</type>
            <joint name="${prefix}Revolute_4">
                <hardwareInterface>hardware_interface/EffortJointInterface</hardwareInterface>
            </joint>
            <actuator name="${prefix}Revolute_4_actr">
                <hardwareInterface>hardware_interface/EffortJointInterface</hardwareInterface>
                <mechanicalReduction>1</mechanicalReduction>
            </actuator>
        </transmission>
        <transmission name="${prefix}Revolute_5_tran">
            <type>transmission_interface/SimpleTransmission</type>
            <joint name="${prefix}Revolute_5">
                <hardwareInterface>hardware_interface/EffortJointInterface</hardwareInterface>
            </joint>
            <actuator name="${prefix}Revolute_5_actr">
                <hardwareInterface>hardware_interface/EffortJointInterface</hardwareInterface>
                <mechanicalReduction>1</mechanicalReduction>
            </actuator>
        </transmission>
        <transmission name="${prefix}Revolute_6_tran">
            <type>transmission_interface/SimpleTransmission</type>
            <joint name="${prefix}Revolute_6">
                <hardwareInterface>hardware_interface/EffortJointInterface</hardwareInterface>
            </joint>
            <actuator name="${prefix}Revolute_6_actr">
                <hardwareInterface>hardware_interface/EffortJointInterface</hardwareInterface>
                <mechanicalReduction>1</mechanicalReduction>
            </actuator>
        </transmission>
        <transmission name="${prefix}Slider_1_tran">
            <type>transmission_interface/SimpleTransmission</type>
            <joint name="${prefix}Slider_1">
                <hardwareInterface>hardware_interface/EffortJointInterface</hardwareInterface>
            </joint>
            <actuator name="${prefix}Slider_1_actr">
                <hardwareInterface>hardware_interface/EffortJointInterface</hardwareInterface>
                <mechanicalReduction>1</mechanicalReduction>
            </actuator>
        </transmission>
        <transmission name="${prefix}Slider_2_tran">
            <type>transmission_interface/SimpleTransmission</type>
            <joint name="${prefix}Slider_2">
                <hardwareInterface>hardware_interface/EffortJointInterface</hardwareInterface>
            </joint>
            <actuator name="${prefix}Slider_2_actr">
                <hardwareInterface>hardware_interface/EffortJointInterface</hardwareInterface>
                <mechanicalReduction>1</mechanicalReduction>
            </actuator>
        </transmission>

        <!-- ROS2 Control for this arm instance -->
        <ros2_control name="${prefix}arm" type="system">
            <hardware>
                <plugin>mock_components/GenericSystem</plugin>
            </hardware>
            <joint name="${prefix}Revolute_1">
                <command_interface name="position"/>
                <state_interface name="position"/>
                <state_interface name="velocity"/>
            </joint>
            <joint name="${prefix}Revolute_2">
                <command_interface name="position"/>
                <state_interface name="position"/>
                <state_interface name="velocity"/>
            </joint>
            <joint name="${prefix}Revolute_3">
                <command_interface name="position"/>
                <state_interface name="position"/>
                <state_interface name="velocity"/>
            </joint>
            <joint name="${prefix}Revolute_4">
                <command_interface name="position"/>
                <state_interface name="position"/>
                <state_interface name="velocity"/>
            </joint>
            <joint name="${prefix}Revolute_5">
                <command_interface name="position"/>
                <state_interface name="position"/>
                <state_interface name="velocity"/>
            </joint>
            <joint name="${prefix}Revolute_6">
                <command_interface name="position"/>
                <state_interface name="position"/>
                <state_interface name="velocity"/>
            </joint>
            <joint name="${prefix}Slider_1">
                <command_interface name="position"/>
                <state_interface name="position"/>
                <state_interface name="velocity"/>
            </joint>
            <joint name="${prefix}Slider_2">
                <command_interface name="position"/>
                <state_interface name="position"/>
                <state_interface name="velocity"/>
            </joint>
        </ros2_control>
    </xacro:macro>

    <!-- Create the world link -->
    <link name="world"/>

    <!-- Create left arm instance -->
    <xacro:arm_instance 
        prefix="left_" 
        base_origin_xyz="$(arg left_origin_xyz)" 
        base_origin_rpy="$(arg left_origin_rpy)"
        Revolute_1_xyz="0.0 0.0 0.0555"
        Revolute_1_rpy="0 0 1.57"
        Revolute_2_xyz="-3.7e-05 0.024464 0.06805"
        Revolute_2_rpy="0 0 0"
        Revolute_3_xyz="0.034861 -0.011969 0.43175"
        Revolute_3_rpy="0 0 0"
        Revolute_4_xyz="0.420611 -0.012207 -0.0001"
        Revolute_4_rpy="0 0 0"
        Revolute_5_xyz="0.078583 0.01897 0.0"
        Revolute_5_rpy="0 0 0"
        Revolute_6_xyz="1.7e-05 -0.0189 -0.0648"
        Revolute_6_rpy="0 0 0"
        Rigid_7_xyz="-5e-05 0.0 -0.045"
        Rigid_7_rpy="0 0 0"
        Slider_1_xyz="0.055 7.3e-05 -0.008"
        Slider_1_rpy="0 0 0"
        Slider_2_xyz="-0.055 -7.2e-05 -0.008"
        Slider_2_rpy="0 0 0"
    />

    <!-- Create right arm instance -->
    <xacro:arm_instance 
        prefix="right_" 
        base_origin_xyz="$(arg right_origin_xyz)" 
        base_origin_rpy="$(arg right_origin_rpy)"
        Revolute_1_xyz="0.0 0.0 0.0555"
        Revolute_1_rpy="0 0 -1.57"
        Revolute_2_xyz="-3.7e-05 0.024464 0.06805"
        Revolute_2_rpy="0 0 0"
        Revolute_3_xyz="0.034861 -0.011969 0.43175"
        Revolute_3_rpy="0 0 0"
        Revolute_4_xyz="0.420611 -0.012207 -0.0001"
        Revolute_4_rpy="0 0 0"
        Revolute_5_xyz="0.078583 0.01897 0.0"
        Revolute_5_rpy="0 0 0"
        Revolute_6_xyz="1.7e-05 -0.0189 -0.0648"
        Revolute_6_rpy="0 0 0"
        Rigid_7_xyz="-5e-05 0.0 -0.045"
        Rigid_7_rpy="0 0 0"
        Slider_1_xyz="0.055 7.3e-05 -0.008"
        Slider_1_rpy="0 0 0"
        Slider_2_xyz="-0.055 -7.2e-05 -0.008"
        Slider_2_rpy="0 0 0"
    />

</robot>