<?xml version="1.0" ?>
<robot name="blue_seiretu" xmlns:xacro="http://www.ros.org/wiki/xacro">

<xacro:include filename="$(find blue_seiretu_description)/urdf/materials.xacro" />
<xacro:include filename="$(find blue_seiretu_description)/urdf/blue_seiretu.trans" />
<link name="base_link">
  <inertial>
    <origin xyz="1.8626252290206704 -0.5308186921199336 0.016889068327243004" rpy="0 0 0"/>
    <mass value="2.198783634355126"/>
    <inertia ixx="0.002972" iyy="0.126512" izz="0.127755" ixy="-0.002307" iyz="0.000304" ixz="0.004032"/>
  </inertial>
  <visual>
    <origin xyz="0 0 0" rpy="0 0 0"/>
    <geometry>
      <mesh filename="package://blue_seiretu_description/meshes/base_link.stl" scale="0.001 0.001 0.001"/>
    </geometry>
    <material name="steel_satin"/>
  </visual>
  <collision>
    <origin xyz="0 0 0" rpy="0 0 0"/>
    <geometry>
      <mesh filename="package://blue_seiretu_description/meshes/base_link.stl" scale="0.001 0.001 0.001"/>
    </geometry>
  </collision>
</link>

<link name="blue_seiretu_1">
  <inertial>
    <origin xyz="0.06569597903167557 -0.1195516608327013 0.09204470816379795" rpy="0 0 0"/>
    <mass value="0.22394819815220426"/>
    <inertia ixx="0.000651" iyy="0.000188" izz="0.000754" ixy="-1.4e-05" iyz="3.8e-05" ixz="-3.1e-05"/>
  </inertial>
  <visual>
    <origin xyz="0.023506 0.51118 -0.019391" rpy="0 0 0"/>
    <geometry>
      <mesh filename="package://blue_seiretu_description/meshes/blue_seiretu_1.stl" scale="0.001 0.001 0.001"/>
    </geometry>
    <material name="steel_satin"/>
  </visual>
  <collision>
    <origin xyz="0.023506 0.51118 -0.019391" rpy="0 0 0"/>
    <geometry>
      <mesh filename="package://blue_seiretu_description/meshes/blue_seiretu_1.stl" scale="0.001 0.001 0.001"/>
    </geometry>
  </collision>
</link>

<joint name="blue_slider" type="prismatic">
  <origin xyz="-0.023506 -0.51118 0.019391" rpy="0 0 0"/>
  <parent link="base_link"/>
  <child link="blue_seiretu_1"/>
  <axis xyz="1.0 -0.0 0.0"/>
  <limit upper="0.0" lower="-0.457" effort="100" velocity="100"/>
</joint>

</robot>
