<?xml version="1.0" ?>
<!-- =================================================================================== -->
<!-- |    This document was autogenerated by xacro from /home/a/ws_moveit2/src/red_seiretu_description-20250907T180457Z-1-001/red_seiretu_description/urdf/red_seiretu.xacro | -->
<!-- |    EDITING THIS FILE BY HAND IS NOT RECOMMENDED                                 | -->
<!-- =================================================================================== -->
<robot name="red_seiretu">
  <material name="silver_default">
    <color rgba="0.700 0.700 0.700 1.000"/>
  </material>
  <material name="opaque202209238">
    <color rgba="0.792156862745098 0.8196078431372549 0.9333333333333333 1.0"/>
  </material>
  <material name="steel_satin">
    <color rgba="0.6274509803921569 0.6274509803921569 0.6274509803921569 1.0"/>
  </material>
  <transmission name="red_slider_tran">
    <type>transmission_interface/SimpleTransmission</type>
    <joint name="red_slider">
      <hardwareInterface>hardware_interface/EffortJointInterface</hardwareInterface>
    </joint>
    <actuator name="red_slider_actr">
      <hardwareInterface>hardware_interface/EffortJointInterface</hardwareInterface>
      <mechanicalReduction>1</mechanicalReduction>
    </actuator>
  </transmission>
  <link name="red_seiretu_base_link">
    <inertial>
      <origin rpy="0 0 0" xyz="1.8626252290206704 -0.5308186921199336 0.016889068327243004"/>
      <mass value="2.198783634355126"/>
      <inertia ixx="0.002972" ixy="-0.002307" ixz="0.004032" iyy="0.126512" iyz="0.000304" izz="0.127755"/>
    </inertial>
    <visual>
      <origin rpy="0 0 0" xyz="0 0 0"/>
      <geometry>
        <mesh filename="package://red_seiretu_description/meshes/base_link.stl" scale="0.001 0.001 0.001"/>
      </geometry>
      <material name="steel_satin"/>
    </visual>
    <collision>
      <origin rpy="0 0 0" xyz="0 0 0"/>
      <geometry>
        <mesh filename="package://red_seiretu_description/meshes/base_link.stl" scale="0.001 0.001 0.001"/>
      </geometry>
    </collision>
  </link>
  <link name="red_seiretu_2">
    <inertial>
      <origin rpy="0 0 0" xyz="0.06569597903167912 -0.11955166083270141 0.09204470816379487"/>
      <mass value="0.22394819815220426"/>
      <inertia ixx="0.000651" ixy="-1.4e-05" ixz="-3.1e-05" iyy="0.000188" iyz="3.8e-05" izz="0.000754"/>
    </inertial>
    <visual>
      <origin rpy="0 0 0" xyz="-2.236494 0.51118 -0.019391"/>
      <geometry>
        <mesh filename="package://red_seiretu_description/meshes/red_seiretu_2.stl" scale="0.001 0.001 0.001"/>
      </geometry>
      <material name="steel_satin"/>
    </visual>
    <collision>
      <origin rpy="0 0 0" xyz="-2.236494 0.51118 -0.019391"/>
      <geometry>
        <mesh filename="package://red_seiretu_description/meshes/red_seiretu_2.stl" scale="0.001 0.001 0.001"/>
      </geometry>
    </collision>
  </link>
  <joint name="red_slider" type="prismatic">
    <origin rpy="0 0 0" xyz="2.236494 -0.51118 0.019391"/>
    <parent link="red_seiretu_base_link"/>
    <child link="red_seiretu_2"/>
    <axis xyz="1.0 0.0 -0.0"/>
    <limit effort="100" lower="-0.457" upper="0.0" velocity="100"/>
  </joint>
</robot>
